<?xml version="1.0"?>
<!-- Materials -->
<robot xmlns:xacro="http://www.ros.org/wiki/xacro" name="arms">

  <!-- PROPERTIES-->
  <xacro:include filename="$(find cmr_description)/urdf/body/arms_properties.xacro" />

  <!-- MACROS -->
  <xacro:include filename="$(find cmr_description)/urdf/macros.xacro" />

  <link name="arm_right_link">

    <inertial>
      <mass value="${armMass}" /> <!--TODO: Find correct value-->
      <inertia
        ixx="${armIxx}"
        ixy = "0"
        ixz = "0"
        iyy="${armIyy}"
        iyz = "0"
        izz="${armIzz}"
        />
      </inertial>
      <visual name='arm'>
        <geometry>
          <mesh filename="package://cmr_description/meshes/arm.STL" scale="1 1 1"/>
        </geometry>
        <material name="White" />
      </visual>
    </link>
    <joint name="arm_right_joint" type="revolute">
      <origin xyz="${armRightOffsetX} ${armRightOffsetY} ${armRightOffsetZ}" rpy="${-pi/2} 0 -${pi/2}" />
      <parent link="torso_link" />
      <child link="arm_right_link" />
      <limit effort="30" velocity="${armVelLim}" lower="${armLowerLim}" upper="${armUpperLim}" />
    </joint>

  <link name="arm_left_link">

    <inertial>
      <mass value="${armMass}" /> <!--TODO: Find correct value-->
      <inertia
        ixx="${armIxx}"
        ixy = "0"
        ixz = "0"
        iyy="${armIyy}"
        iyz = "0"
        izz="${armIzz}"
        />
      </inertial>
      <visual name='arm'>
	<origin xyz="0 0 0" rpy="0 ${pi} 0" />
        <geometry>
          <mesh filename="package://cmr_description/meshes/arm.STL" scale="1 1 1"/>
        </geometry>
      <material name="White" />
      </visual>
    </link>
    <joint name="arm_left_joint" type="revolute">
      <origin xyz="${armLeftOffsetX} ${armLeftOffsetY} ${armLeftOffsetZ}" rpy="${-pi/2} 0 -${pi/2}" />
      <parent link="torso_link" />
      <child link="arm_left_link" />
      <limit effort="30" velocity="${armVelLim}" lower="${armLowerLim}" upper="${armUpperLim}" />
    </joint>

  <transmission name="arm_right_tran">
    <type>transmission_interface/SimpleTransmission</type>
    <joint name="arm_right_joint">
      <hardwareInterface>PositionJointInterface</hardwareInterface>
    </joint>
    <actuator name="arm_right_motor">
      <hardwareInterface>PositionJointInterface</hardwareInterface>
      <mechanicalReduction>1</mechanicalReduction>
    </actuator>
  </transmission>

  <transmission name="arm_left_tran">
    <type>transmission_interface/SimpleTransmission</type>
    <joint name="arm_left_joint">
      <hardwareInterface>PositionJointInterface</hardwareInterface>
    </joint>
    <actuator name="arm_left_motor">
      <hardwareInterface>PositionJointInterface</hardwareInterface>
      <mechanicalReduction>1</mechanicalReduction>
    </actuator>
  </transmission>

</robot>
