<?xml version="1.0"?>
<!-- Materials -->
<robot xmlns:xacro="http://www.ros.org/wiki/xacro" name="ears">

  <!-- PROPERTIES-->
  <xacro:include filename="$(find cmr_description)/urdf/body/ears_properties.xacro" />

  <!-- MACROS -->
  <xacro:include filename="$(find cmr_description)/urdf/macros.xacro" />

  <!-- GAZEBO -->
  <xacro:include filename="$(find cmr_description)/urdf/body/ears_gazebo.xacro" />

  <link name="ear_right_link">

    <inertial>
      <mass value="${earMass}" /> <!--TODO: Find correct value-->
      <inertia
        ixx="${earIxx}"
        ixy = "0"
        ixz = "0"
        iyy="${earIyy}"
        iyz = "0"
        izz="${earIzz}"
        />
      </inertial>
      <visual name='ear'>
        <geometry>
          <mesh filename="package://cmr_description/meshes/ear.STL" scale="1 1 1"/>
        </geometry>
        <material name="White" />
      </visual>
    </link>
    <joint name="ear_right_joint" type="revolute">
      <origin xyz="${earRightOffsetX} ${earRightOffsetY} ${earRightOffsetZ}" rpy="${-pi/2 + pi + pi/6} 0 -${pi/2}" />
      <parent link="head_link" />
      <child link="ear_right_link" />
      <limit effort="30" velocity="${earVelLim}" lower="${earLowerLim}" upper="${earUpperLim}" />
    </joint>

  <link name="ear_left_link">

    <inertial>
      <mass value="${earMass}" /> <!--TODO: Find correct value-->
      <inertia
        ixx="${earIxx}"
        ixy = "0"
        ixz = "0"
        iyy="${earIyy}"
        iyz = "0"
        izz="${earIzz}"
        />
      </inertial>
      <visual name='ear'>
	<origin xyz="0 0 0" rpy="0 ${pi} 0" />
        <geometry>
          <mesh filename="package://cmr_description/meshes/ear.STL" scale="1 1 1"/>
        </geometry>
       <material name="White" />
      </visual>
    </link>
    <joint name="ear_left_joint" type="revolute">
      <origin xyz="${earLeftOffsetX} ${earLeftOffsetY} ${earLeftOffsetZ}" rpy="${-pi/2 + pi + pi/6} 0 -${pi/2}" />
      <parent link="head_link" />
      <child link="ear_left_link" />
      <limit effort="30" velocity="${earVelLim}" lower="${earLowerLim}" upper="${earUpperLim}" />
    </joint>

  <transmission name="ear_right_tran">
    <type>transmission_interface/SimpleTransmission</type>
    <joint name="ear_right_joint">
      <hardwareInterface>PositionJointInterface</hardwareInterface>
    </joint>
    <actuator name="ear_right_motor">
      <hardwareInterface>PositionJointInterface</hardwareInterface>
      <mechanicalReduction>1</mechanicalReduction>
    </actuator>
  </transmission>

  <transmission name="ear_left_tran">
    <type>transmission_interface/SimpleTransmission</type>
    <joint name="ear_left_joint">
      <hardwareInterface>PositionJointInterface</hardwareInterface>
    </joint>
    <actuator name="ear_left_motor">
      <hardwareInterface>PositionJointInterface</hardwareInterface>
      <mechanicalReduction>1</mechanicalReduction>
    </actuator>
  </transmission>
</robot>
